Workbook

Sheet Maestra
A1: Correo del candidato | B1: Nombre del candidato | C1: Tipo de identificación | D1: Número de documento de identificación | E1: Género con el que te identificas | F1: ¿Cuál es tu edad? | G1: ¿Actualmente estás cursando un pregrado universitario? | H1: Ciudad en la que resides actualmente | I1: Lugar en el que estarías dispuesto/a a realizar tus prácticas | J1: A que universidad perteneces | K1: ¿Cuál?. | L1: Nombre del programa académico | M1: ¿Cuál? | N1: ¿Debes cursar asignaturas durante la realización de tus prácticas? | O1: ¿Anteriormente ha tenido vinculación como aprendiz SENA? | P1: Nivel de inglés | Q1: Nivel de manejo de Excel | R1: Primer área de interés para realizar la práctica | S1: Vacantes Producción (Operaciones) | T1: Vacantes Finanzas | U1: Vacantes Talento | V1: Vacantes Ventas | W1: Segunda área de interés para realizar la práctica | X1: Vacantes Producción (Operaciones)2 | Y1: Vacantes Finanzas3 | Z1: Vacantes Talento4 | AA1: Vacantes Ventas5 | AB1: ¿Has trabajado anteriormente para nuestra compañía? | AC1: ¿Tienes algún familiar laborado con la compañía? | AD1: Si tu respuesta fue "Sí", indica el parentesco y nombre completo (Ejemplo: Madre – Rosa Elena Medina Delgado): | AE1: ¿Tienes algún familiar que sea o labore con un proveedor de la compañía? | AF1: Si tu respuesta fue "Sí", indica e parentesco y nombre completo (Ejemplo: Madre - Rosa Elena Medina Delgado): | AG1: ¿Tienes algún familiar que sea o labore con un cliente de la compañía? | AH1: Si tu respuesta fue "Sí", indica el parentesco y nombre completo (Ejemplo: Madre - Rosa Elena Medina Delgado): | AI1: ¿Tienes algún familiar que sea o labore con la competencia de la compañía? | AJ1: Si tu respuesta fue "Sí", indica el parentesco y nombre completo (Ejemplo: Madre - Rosa Elena Medina Delgado): | AK1: ¿Por qué medio te enteraste de nuestra convocatoria? | AL1: Nombre de la etapa | AM1: Día | AN1: Hora | AO1: Teléfono | AP1: Dirección | AQ1: Magneto ERI | AR1: Magneto % | AS1: Encargado | AT1: Vacante sugerida | AU1: Confirmación | AV1: Comentarios | AW1: Carrera | AX1: Teléfono contacto | AY1: Site | AZ1: Fecha creatón | BA1: Horario creatón
A2: jepr.240505@gmail.com | B2: Juan Esteban Paez Ruiz | C2: Cédula de ciudadanía | D2: 1031641933 | E2: Hombre | F2: 22 | G2: TRUE | I2: Bogotá | J2: Universidad del Bosque | L2: Estadística | N2: TRUE | O2: FALSE | P2: Intermedio | Q2: Avanzado | R2: Tecnología | U2: Área financiera | W2: Talento | AB2: FALSE | AC2: FALSE | AE2: FALSE | AG2: FALSE | AI2: FALSE | AK2: LinkedIn | AL2: CREATÓN | AM2: 46278 | AN2: 0.80265046 | AO2: 310 3824756 | AP2: Calle 83 103C-55, 111011 Bogota, D.C., Colombia | AQ2: DP | AR2: 74.5 | AS2: Cata | AT2: Area financiera (PPM) | AU2: NO | AV2: OK | AW2: =IF(L2="Otra",IF(M2="","Otra",M2&""),L2&"") -> Estadística | AX2: =IF(OR(AO2="",AO2=0),"",TRIM(AO2)) -> 310 3824756 | AY2: =IFERROR(INDEX(Vacantes!$C:$C,MATCH(AT2,Vacantes!$A:$A,0)),"") -> 127 | AZ2: =IFERROR(INDEX(Vacantes!$D:$D,MATCH(AT2,Vacantes!$A:$A,0)),"") -> 13 de octubre de 2026 | BA2: =IFERROR(INDEX(Vacantes!$E:$E,MATCH(AT2,Vacantes!$A:$A,0)),"") -> 7:30 a.m. a 11:30 a.m.
A3: gabrielalopezp5@gmail.com | B3: Gabriela Lopez | C3: Cédula de ciudadanía | D3: 1034516871 | E3: Mujer | F3: 21 | G3: TRUE | H3: BOGOTÁ | I3: Bogotá | J3: Universidad de los Andes | L3: Economía | N3: FALSE | O3: FALSE | P3: Avanzado | Q3: Intermedio | R3: Finanzas | W3: Compras | Y3: Finanzas Impuestos | AB3: FALSE | AC3: FALSE | AE3: FALSE | AG3: FALSE | AI3: FALSE | AK3: LinkedIn | AL3: CREATÓN | AM3: 46265 | AN3: 0.56325231 | AO3: 316 2398383 | AP3: Calle 84 9-85, 110221 Bogota, D.C., Colombia | AQ3: DP | AR3: 79.7 | AS3: Santi | AT3: Area financiera (PPM) | AU3: NO | AV3: OK | AW3: =IF(L3="Otra",IF(M3="","Otra",M3&""),L3&"") -> Economía | AX3: =IF(OR(AO3="",AO3=0),"",TRIM(AO3)) -> 316 2398383 | AY3: =IFERROR(INDEX(Vacantes!$C:$C,MATCH(AT3,Vacantes!$A:$A,0)),"") -> 127 | AZ3: =IFERROR(INDEX(Vacantes!$D:$D,MATCH(AT3,Vacantes!$A:$A,0)),"") -> 13 de octubre de 2026 | BA3: =IFERROR(INDEX(Vacantes!$E:$E,MATCH(AT3,Vacantes!$A:$A,0)),"") -> 7:30 a.m. a 11:30 a.m.
A4: mateo.fontecha@outlook.com | B4: Mateo Fontecha | C4: Cédula de ciudadanía | D4: 1000364978 | E4: Hombre | F4: 25 | G4: TRUE | H4: BOGOTA | I4: Bogotá | J4: Universidad de los Andes | L4: Economía | N4: FALSE | O4: FALSE | P4: Avanzado | Q4: Intermedio | R4: Finanzas | W4: Asuntos Corporativos | Y4: Finanzas Impuestos | AB4: FALSE | AC4: FALSE | AE4: FALSE | AG4: FALSE | AI4: FALSE | AK4: LinkedIn | AL4: CREATÓN | AM4: 46266 | AN4: 0.45931713 | AO4: 0 | AP4: Carrera 52A 57B-33, 111321 Bogota, D.C., Colombia | AQ4: DP | AR4: 89.6 | AS4: Cata | AT4: Asuntos Corporativos | AU4: NO | AV4: OK | AW4: =IF(L4="Otra",IF(M4="","Otra",M4&""),L4&"") -> Economía | AX4: =IF(OR(AO4="",AO4=0),"",TRIM(AO4)) | AY4: =IFERROR(INDEX(Vacantes!$C:$C,MATCH(AT4,Vacantes!$A:$A,0)),"") -> 127 | AZ4: =IFERROR(INDEX(Vacantes!$D:$D,MATCH(AT4,Vacantes!$A:$A,0)),"") -> 13 de octubre de 2026 | BA4: =IFERROR(INDEX(Vacantes!$E:$E,MATCH(AT4,Vacantes!$A:$A,0)),"") -> 1:30 p.m. a 5:30 p.m.
A5: juanjeronimo1508@gmail.com | B5: Juan David Jerónimo González | C5: Cédula de ciudadanía | D5: 1027525480 | E5: Hombre | F5: 20 | G5: TRUE | I5: Bogotá | J5: Universidad del Bosque | L5: Estadística | N5: TRUE | O5: FALSE | P5: Intermedio | Q5: Avanzado | R5: Tecnología | U5: Compensación y Beneficios | W5: Talento | AB5: FALSE | AC5: FALSE | AE5: FALSE | AG5: FALSE | AI5: FALSE | AK5: Instagram | AL5: CREATÓN | AM5: 46255 | AN5: 0.4500463 | AO5: 324 4326262 | AP5: Carrera 33A 56 S-14, 110611 Bogota, D.C., Colombia | AQ5: DP | AR5: 90.8 | AS5: Santi | AT5: Compensación y beneficios | AU5: NO | AV5: OK | AW5: =IF(L5="Otra",IF(M5="","Otra",M5&""),L5&"") -> Estadística | AX5: =IF(OR(AO5="",AO5=0),"",TRIM(AO5)) -> 324 4326262 | AY5: =IFERROR(INDEX(Vacantes!$C:$C,MATCH(AT5,Vacantes!$A:$A,0)),"") -> 127 | AZ5: =IFERROR(INDEX(Vacantes!$D:$D,MATCH(AT5,Vacantes!$A:$A,0)),"") -> 13 de octubre de 2026 | BA5: =IFERROR(INDEX(Vacantes!$E:$E,MATCH(AT5,Vacantes!$A:$A,0)),"") -> 7:30 a.m. a 11:30 a.m.
A6: johningla15@gmail.com | B6: John Alejandro Rosas Guerrero | C6: Cédula de ciudadanía | D6: 1013259327 | E6: Hombre | F6: 21 | G6: TRUE | I6: Bogotá | J6: Universidad EAFIT | L6: Finanzas | N6: FALSE | O6: FALSE | P6: Intermedio | Q6: Avanzado | R6: Finanzas | W6: Compras | Y6: Finanzas Impuestos | AB6: FALSE | AC6: FALSE | AE6: FALSE | AG6: FALSE | AI6: FALSE | AK6: LinkedIn | AL6: CREATÓN | AM6: 46255 | AN6: 0.4146875 | AO6: 0 | AP6: Calle 33AA 78A-17, 050031 Medellin, Colombia | AQ6: DP | AR6: 93.3 | AS6: Cata | AT6: Compras (Procurement PPM Reporting) | AU6: NO | AV6: OK | AW6: =IF(L6="Otra",IF(M6="","Otra",M6&""),L6&"") -> Finanzas | AX6: =IF(OR(AO6="",AO6=0),"",TRIM(AO6)) | AY6: =IFERROR(INDEX(Vacantes!$C:$C,MATCH(AT6,Vacantes!$A:$A,0)),"") -> 127 | AZ6: =IFERROR(INDEX(Vacantes!$D:$D,MATCH(AT6,Vacantes!$A:$A,0)),"") -> 13 de octubre de 2026 | BA6: =IFERROR(INDEX(Vacantes!$E:$E,MATCH(AT6,Vacantes!$A:$A,0)),"") -> 7:30 a.m. a 11:30 a.m.
A7: santiago.zambrano1008@gmail.com | B7: Santiago Zambrano Iregui | C7: Cédula de ciudadanía | D7: 1032876688 | E7: Hombre | F7: 21 | G7: TRUE | H7: Tabio | I7: Bogotá | J7: Universidad de La Sabana | L7: Administración de Empresas | N7: FALSE | O7: FALSE | P7: Avanzado | Q7: Avanzado | R7: Marketing | W7: Ventas | AA7: Gestión de Ejecución Premium | AB7: FALSE | AC7: FALSE | AE7: FALSE | AG7: FALSE | AI7: FALSE | AK7: Instagram | AL7: CREATÓN | AM7: 46258 | AN7: 0.39797454 | AO7: 318 8147439 | AP7: Tabio Cundinamarca, 250237 Tabio, Colombia | AQ7: DP | AR7: 84.3 | AS7: Santi | AT7: Comunicaciones | AU7: NO | AV7: OK | AW7: =IF(L7="Otra",IF(M7="","Otra",M7&""),L7&"") -> Administración de Empresas | AX7: =IF(OR(AO7="",AO7=0),"",TRIM(AO7)) -> 318 8147439 | AY7: =IFERROR(INDEX(Vacantes!$C:$C,MATCH(AT7,Vacantes!$A:$A,0)),"") -> 127 | AZ7: =IFERROR(INDEX(Vacantes!$D:$D,MATCH(AT7,Vacantes!$A:$A,0)),"") -> 13 de octubre de 2026 | BA7: =IFERROR(INDEX(Vacantes!$E:$E,MATCH(AT7,Vacantes!$A:$A,0)),"") -> 1:30 p.m. a 5:30 p.m.
A8: selmasanabriad@gmail.com | B8: Selma Melisa Andrea Sanabria Durango | C8: Cédula de ciudadanía | D8: 1066872533 | E8: Mujer | F8: 18 | G8: TRUE | H8: VALLEDUPAR | I8: Bogotá | J8: Universidad del Bosque | L8: Marketing / Mercadeo | N8: FALSE | O8: FALSE | P8: Intermedio | Q8: Intermedio | R8: Marketing | W8: Comunicaciones | AB8: FALSE | AC8: FALSE | AE8: FALSE | AG8: FALSE | AI8: FALSE | AK8: Instagram | AL8: CREATÓN | AM8: 46277 | AN8: 0.79758102 | AO8: 313 6263013 | AP8: Valledupar, Colombia | AQ8: DP | AR8: 73.2 | AS8: Cata | AT8: Comunicaciones | AU8: NO | AV8: OK | AW8: =IF(L8="Otra",IF(M8="","Otra",M8&""),L8&"") -> Marketing / Mercadeo | AX8: =IF(OR(AO8="",AO8=0),"",TRIM(AO8)) -> 313 6263013 | AY8: =IFERROR(INDEX(Vacantes!$C:$C,MATCH(AT8,Vacantes!$A:$A,0)),"") -> 127 | AZ8: =IFERROR(INDEX(Vacantes!$D:$D,MATCH(AT8,Vacantes!$A:$A,0)),"") -> 13 de octubre de 2026 | BA8: =IFERROR(INDEX(Vacantes!$E:$E,MATCH(AT8,Vacantes!$A:$A,0)),"") -> 1:30 p.m. a 5:30 p.m.
A9: carolinaandrea6470@gmail.com | B9: Carolina Hernandez | C9: Cédula de ciudadanía | D9: 1023372339 | E9: Mujer | F9: 20 | G9: TRUE | H9: Bogota | I9: Bogotá | J9: Otra | K9: Universidad EAN | L9: Negocios Internacionales | N9: FALSE | O9: FALSE | P9: Intermedio | Q9: Intermedio | R9: Logística | W9: Marketing | AB9: FALSE | AC9: FALSE | AE9: FALSE | AG9: FALSE | AI9: FALSE | AK9: LinkedIn | AL9: CREATÓN | AM9: 46277 | AN9: 0.97130787 | AO9: 3106091858 | AP9: Calle 70D Sur 79-45, 110741 Bogota, D.C., Colombia | AQ9: DP | AR9: 75.2 | AS9: Cata | AT9: Logística T2 (Safety & DPO T2) | AU9: NO | AV9: OK | AW9: =IF(L9="Otra",IF(M9="","Otra",M9&""),L9&"") -> Negocios Internacionales | AX9: =IF(OR(AO9="",AO9=0),"",TRIM(AO9)) -> 3106091858 | AY9: =IFERROR(INDEX(Vacantes!$C:$C,MATCH(AT9,Vacantes!$A:$A,0)),"") -> 127 | AZ9: =IFERROR(INDEX(Vacantes!$D:$D,MATCH(AT9,Vacantes!$A:$A,0)),"") -> 13 de octubre de 2026 | BA9: =IFERROR(INDEX(Vacantes!$E:$E,MATCH(AT9,Vacantes!$A:$A,0)),"") -> 7:30 a.m. a 11:30 a.m.
A10: angelamendozaeslava2000@gmail.com | B10: Angela Mendoza Eslava | C10: Cédula de ciudadanía | D10: 1018432023 | E10: Mujer | F10: 18 | G10: TRUE | H10: BOGOTA | I10: Bogotá | J10: Pontificia Universidad Javeriana | L10: Administración de Empresas | N10: FALSE | O10: FALSE | P10: Avanzado | Q10: Avanzado | R10: Talento | U10: Atracción de Talento y Marca Empleadora | W10: Talento | Z10: Support | AB10: FALSE | AC10: FALSE | AE10: FALSE | AG10: FALSE | AI10: FALSE | AK10: Página Web Oficial | AL10: CREATÓN | AM10: 46268 | AN10: 0.52506944 | AO10: 305 3700517 | AP10: Calle 83A 118-29, 111011 Bogota, D.C., Colombia | AQ10: DP | AR10: 82.2 | AS10: Cata | AT10: People Support 2 | AU10: NO | AV10: OK | AW10: =IF(L10="Otra",IF(M10="","Otra",M10&""),L10&"") -> Administración de Empresas | AX10: =IF(OR(AO10="",AO10=0),"",TRIM(AO10)) -> 305 3700517 | AY10: =IFERROR(INDEX(Vacantes!$C:$C,MATCH(AT10,Vacantes!$A:$A,0)),"") -> 127 | AZ10: =IFERROR(INDEX(Vacantes!$D:$D,MATCH(AT10,Vacantes!$A:$A,0)),"") -> 13 de octubre de 2026 | BA10: =IFERROR(INDEX(Vacantes!$E:$E,MATCH(AT10,Vacantes!$A:$A,0)),"") -> 1:30 p.m. a 5:30 p.m.
A11: acastanedaruiz55@gmail.com | B11: Alejandro Castaneda Ruiz | C11: Cédula de ciudadanía | D11: 1014858199 | E11: Hombre | F11: 21 | G11: TRUE | H11: Bogota | I11: Bogotá | J11: Universidad de los Andes | L11: Economía | N11: FALSE | O11: FALSE | P11: Avanzado | Q11: Intermedio | R11: Tecnología | T11: Finanzas Impuestos | W11: Finanzas | AB11: FALSE | AC11: FALSE | AE11: FALSE | AG11: FALSE | AI11: FALSE | AK11: LinkedIn | AL11: CREATÓN | AM11: 46265 | AN11: 0.56325231 | AO11: 310 8888133 | AP11: Calle 146A 58B-22, 111156 Bogota, D.C., Colombia | AQ11: DP | AR11: 88.9 | AS11: Cata | AT11: Tecnología (JR Data Scientist) | AU11: NO | AV11: OK | AW11: =IF(L11="Otra",IF(M11="","Otra",M11&""),L11&"") -> Economía | AX11: =IF(OR(AO11="",AO11=0),"",TRIM(AO11)) -> 310 8888133 | AY11: =IFERROR(INDEX(Vacantes!$C:$C,MATCH(AT11,Vacantes!$A:$A,0)),"") -> 127 | AZ11: =IFERROR(INDEX(Vacantes!$D:$D,MATCH(AT11,Vacantes!$A:$A,0)),"") -> 13 de octubre de 2026 | BA11: =IFERROR(INDEX(Vacantes!$E:$E,MATCH(AT11,Vacantes!$A:$A,0)),"") -> 7:30 a.m. a 11:30 a.m.
A12: julim2702@gmail.com | B12: Juliana Manrique Monroy | C12: Cédula de ciudadanía | D12: 1000612606 | E12: Mujer | F12: 23 | G12: TRUE | I12: Bogotá | J12: Universidad del Rosario | L12: Marketing / Mercadeo | N12: TRUE | O12: FALSE | P12: Avanzado | Q12: Intermedio | R12: Marketing | W12: Ventas | AA12: BEES | AB12: FALSE | AC12: FALSE | AE12: FALSE | AG12: FALSE | AI12: FALSE | AK12: LinkedIn | AL12: CREATÓN | AM12: 46257 | AN12: 0.77711806 | AO12: 316 2325718 | AP12: Edificio Roger VI, 111321 Bogota, D.C., Colombia | AQ12: DP | AR12: 93.6 | AS12: Cata | AT12: Channel Strategy and Performance (BEES) | AU12: NO | AV12: OK | AW12: =IF(L12="Otra",IF(M12="","Otra",M12&""),L12&"") -> Marketing / Mercadeo | AX12: =IF(OR(AO12="",AO12=0),"",TRIM(AO12)) -> 316 2325718 | AY12: =IFERROR(INDEX(Vacantes!$C:$C,MATCH(AT12,Vacantes!$A:$A,0)),"") -> 127 | AZ12: =IFERROR(INDEX(Vacantes!$D:$D,MATCH(AT12,Vacantes!$A:$A,0)),"") -> 13 de octubre de 2026 | BA12: =IFERROR(INDEX(Vacantes!$E:$E,MATCH(AT12,Vacantes!$A:$A,0)),"") -> 1:30 p.m. a 5:30 p.m.
A13: ottorincon0408@gmail.com | B13: Oto Esteban Rincón Giraldo | C13: Cédula de ciudadanía | D13: 1070589753 | E13: Hombre | F13: 21 | G13: TRUE | H13: BUCARAMANGA | I13: Bogotá | J13: Otra | K13: Universidad de Santander | L13: Otra | M13: Administración de Negocios Internacionales | N13: TRUE | O13: FALSE | P13: Intermedio | Q13: Intermedio | R13: Logística | W13: Compras | AB13: FALSE | AC13: FALSE | AE13: FALSE | AG13: FALSE | AI13: FALSE | AK13: LinkedIn | AL13: CREATÓN | AM13: 46261 | AN13: 0.6196412 | AO13: 305 4120170 | AP13: Torres de Monterrey, 680004 Bucaramanga, Colombia | AQ13: DP | AR13: 88.6 | AS13: Cata | AT13: Compras (Procurement PPM Reporting) | AU13: NO | AV13: OK | AW13: =IF(L13="Otra",IF(M13="","Otra",M13&""),L13&"") -> Administración de Negocios Internacionales | AX13: =IF(OR(AO13="",AO13=0),"",TRIM(AO13)) -> 305 4120170 | AY13: =IFERROR(INDEX(Vacantes!$C:$C,MATCH(AT13,Vacantes!$A:$A,0)),"") -> 127 | AZ13: =IFERROR(INDEX(Vacantes!$D:$D,MATCH(AT13,Vacantes!$A:$A,0)),"") -> 13 de octubre de 2026 | BA13: =IFERROR(INDEX(Vacantes!$E:$E,MATCH(AT13,Vacantes!$A:$A,0)),"") -> 7:30 a.m. a 11:30 a.m.
A14: ricardocubillosc@javeriana.edu.co | B14: Ricardo Cubillos Combariza | C14: Cédula de ciudadanía | D14: 1014859662 | E14: Hombre | F14: 20 | G14: TRUE | H14: BOGOTA | I14: Bogotá | J14: Pontificia Universidad Javeriana | L14: Finanzas | N14: FALSE | O14: FALSE | P14: Avanzado | Q14: Avanzado | R14: Finanzas | U14: Área financiera | W14: Talento | Y14: Finanzas Impuestos | AB14: FALSE | AC14: FALSE | AE14: FALSE | AG14: FALSE | AI14: FALSE | AK14: Página Web Oficial | AL14: CREATÓN | AM14: 46258 | AN14: 0.76322917 | AO14: 321 8574669 | AP14: Calle 117D 57-96, 111111 Bogota, D.C., Colombia | AQ14: DP | AR14: 89.9 | AS14: Cata | AT14: Area financiera (PPM) | AU14: SI | AV14: OK | AW14: =IF(L14="Otra",IF(M14="","Otra",M14&""),L14&"") -> Finanzas | AX14: =IF(OR(AO14="",AO14=0),"",TRIM(AO14)) -> 321 8574669 | AY14: =IFERROR(INDEX(Vacantes!$C:$C,MATCH(AT14,Vacantes!$A:$A,0)),"") -> 127 | AZ14: =IFERROR(INDEX(Vacantes!$D:$D,MATCH(AT14,Vacantes!$A:$A,0)),"") -> 13 de octubre de 2026 | BA14: =IFERROR(INDEX(Vacantes!$E:$E,MATCH(AT14,Vacantes!$A:$A,0)),"") -> 7:30 a.m. a 11:30 a.m.
A15: sanvalentin139@gmail.com | B15: Valentín Moncada Sánchez | C15: Cédula de ciudadanía | D15: 1022939244 | E15: Hombre | F15: 20 | G15: TRUE | H15: Bogotá | I15: Bogotá | J15: Pontificia Universidad Javeriana | L15: Finanzas | N15: TRUE | O15: FALSE | P15: Intermedio | Q15: Intermedio | R15: Finanzas | U15: Área financiera | W15: Talento | Y15: Finanzas Impuestos | AB15: FALSE | AC15: FALSE | AE15: FALSE | AG15: FALSE | AI15: FALSE | AK15: Otros | AL15: CREATÓN | AM15: 46267 | AN15: 0.26954861 | AO15: 319 5528847 | AP15: Carrera 69K 68-59, 111061 Bogota, D.C., Colombia | AQ15: DP | AR15: 86.4 | AS15: Cata | AT15: Area financiera (PPM) | AU15: SI | AV15: OK | AW15: =IF(L15="Otra",IF(M15="","Otra",M15&""),L15&"") -> Finanzas | AX15: =IF(OR(AO15="",AO15=0),"",TRIM(AO15)) -> 319 5528847 | AY15: =IFERROR(INDEX(Vacantes!$C:$C,MATCH(AT15,Vacantes!$A:$A,0)),"") -> 127 | AZ15: =IFERROR(INDEX(Vacantes!$D:$D,MATCH(AT15,Vacantes!$A:$A,0)),"") -> 13 de octubre de 2026 | BA15: =IFERROR(INDEX(Vacantes!$E:$E,MATCH(AT15,Vacantes!$A:$A,0)),"") -> 7:30 a.m. a 11:30 a.m.
A16: cristianbeltran450@gmail.com | B16: Cristian Beltran Mendez | C16: Cédula de ciudadanía | D16: 1027210314 | E16: Hombre | F16: 21 | G16: TRUE | H16: Bogotá | I16: Bogotá | J16: Universidad del Rosario | L16: Analítica de Datos | N16: FALSE | O16: FALSE | P16: Avanzado | Q16: Avanzado | R16: Finanzas | W16: Compras | Y16: Finanzas Impuestos | AB16: FALSE | AC16: FALSE | AE16: FALSE | AG16: FALSE | AI16: FALSE | AK16: Página Web Oficial | AL16: CREATÓN | AM16: 46278 | AN16: 0.67866898 | AO16: 315 6652203 | AP16: Calle 191A 11A-25, 110141 Bogota, D.C., Colombia | AQ16: DP | AR16: 74.5 | AS16: Cata | AT16: Area financiera (PPM) | AU16: SI | AV16: OK | AW16: =IF(L16="Otra",IF(M16="","Otra",M16&""),L16&"") -> Analítica de Datos | AX16: =IF(OR(AO16="",AO16=0),"",TRIM(AO16)) -> 315 6652203 | AY16: =IFERROR(INDEX(Vacantes!$C:$C,MATCH(AT16,Vacantes!$A:$A,0)),"") -> 127 | AZ16: =IFERROR(INDEX(Vacantes!$D:$D,MATCH(AT16,Vacantes!$A:$A,0)),"") -> 13 de octubre de 2026 | BA16: =IFERROR(INDEX(Vacantes!$E:$E,MATCH(AT16,Vacantes!$A:$A,0)),"") -> 7:30 a.m. a 11:30 a.m.
A17: dkarina.th@gmail.com | B17: Danna Karina Tovar Cabezas | C17: Cédula de ciudadanía | D17: 1013102674 | E17: Mujer | F17: 21 | G17: TRUE | H17: BOGOTA D.C. | I17: Bogotá | J17: Universidad Nacional de Colombia | L17: Economía | N17: FALSE | O17: FALSE | P17: Avanzado | Q17: Avanzado | R17: Finanzas | T17: Finanzas Impuestos | W17: Finanzas | Y17: Finanzas Impuestos | AB17: FALSE | AC17: FALSE | AE17: FALSE | AG17: FALSE | AI17: FALSE | AK17: Otros | AL17: CREATÓN | AM17: 46258 | AN17: 0.91048611 | AO17: 3026715667 | AP17: Calle 69B Sur 64, Bogota, D.C., Colombia | AQ17: DP | AR17: 83.7 | AS17: Cata | AT17: Area financiera (PPM) | AU17: SI | AV17: OK | AW17: =IF(L17="Otra",IF(M17="","Otra",M17&""),L17&"") -> Economía | AX17: =IF(OR(AO17="",AO17=0),"",TRIM(AO17)) -> 3026715667 | AY17: =IFERROR(INDEX(Vacantes!$C:$C,MATCH(AT17,Vacantes!$A:$A,0)),"") -> 127 | AZ17: =IFERROR(INDEX(Vacantes!$D:$D,MATCH(AT17,Vacantes!$A:$A,0)),"") -> 13 de octubre de 2026 | BA17: =IFERROR(INDEX(Vacantes!$E:$E,MATCH(AT17,Vacantes!$A:$A,0)),"") -> 7:30 a.m. a 11:30 a.m.
A18: afdelgado@universidadmayor.edu.co | B18: ANDRES FELIPE DELGADO REY | C18: Cédula de ciudadanía | D18: 1000163318 | E18: Hombre | F18: 25 | G18: TRUE | H18: BOGOTA | I18: Bogotá | J18: Otra | K18: Universidad colegio mayor de cundinamarca | L18: Economía | N18: FALSE | O18: FALSE | P18: Intermedio | Q18: Avanzado | R18: Finanzas | T18: Finanzas Impuestos | W18: Finanzas | Y18: Finanzas Impuestos | AB18: FALSE | AC18: FALSE | AE18: FALSE | AG18: FALSE | AI18: FALSE | AK18: Página Web Oficial | AL18: CREATÓN | AM18: 46269 | AN18: 0.24945602 | AO18: 3143611237 | AP18: Carrera 95A 56H S-52, 110711 Bogota, D.C., Colombia | AQ18: DP | AR18: 82.1 | AS18: Cata | AT18: Area financiera (PPM) | AU18: SI | AV18: OK | AW18: =IF(L18="Otra",IF(M18="","Otra",M18&""),L18&"") -> Economía | AX18: =IF(OR(AO18="",AO18=0),"",TRIM(AO18)) -> 3143611237 | AY18: =IFERROR(INDEX(Vacantes!$C:$C,MATCH(AT18,Vacantes!$A:$A,0)),"") -> 127 | AZ18: =IFERROR(INDEX(Vacantes!$D:$D,MATCH(AT18,Vacantes!$A:$A,0)),"") -> 13 de octubre de 2026 | BA18: =IFERROR(INDEX(Vacantes!$E:$E,MATCH(AT18,Vacantes!$A:$A,0)),"") -> 7:30 a.m. a 11:30 a.m.
A19: pericoagudelomariafernanda@gmail.com | B19: Maria Fernanda Perico Agudelo | C19: Cédula de ciudadanía | D19: 1031644605 | E19: Mujer | F19: 21 | G19: TRUE | H19: BOGOTA | I19: Bogotá | J19: Universidad Externado de Colombia | L19: Derecho | N19: FALSE | O19: FALSE | P19: Avanzado | Q19: Básico | R19: Asuntos corporativos | W19: Tecnología | AB19: FALSE | AC19: FALSE | AE19: FALSE | AG19: FALSE | AI19: FALSE | AK19: Otros | AL19: CREATÓN | AM19: 46266 | AN19: 0.68083333 | AO19: 3197010253 | AP19: Calle 159 54-35, 111156 Bogota, D.C., Colombia | AQ19: DP | AR19: 95.5 | AS19: Santi | AT19: Asuntos Corporativos | AU19: SI | AV19: OK | AW19: =IF(L19="Otra",IF(M19="","Otra",M19&""),L19&"") -> Derecho | AX19: =IF(OR(AO19="",AO19=0),"",TRIM(AO19)) -> 3197010253 | AY19: =IFERROR(INDEX(Vacantes!$C:$C,MATCH(AT19,Vacantes!$A:$A,0)),"") -> 127 | AZ19: =IFERROR(INDEX(Vacantes!$D:$D,MATCH(AT19,Vacantes!$A:$A,0)),"") -> 13 de octubre de 2026 | BA19: =IFERROR(INDEX(Vacantes!$E:$E,MATCH(AT19,Vacantes!$A:$A,0)),"") -> 1:30 p.m. a 5:30 p.m.
A20: lunaardila08@hotmail.com | B20: Luna Carolina Ardila Jiménez | C20: Cédula de ciudadanía | D20: 1025528570 | E20: Mujer | F20: 20 | G20: TRUE | H20: Bogotá | I20: Bogotá | J20: Otra | K20: Universidad EAN | L20: Negocios Internacionales | N20: FALSE | O20: FALSE | P20: Intermedio | Q20: Intermedio | R20: Asuntos corporativos | U20: Atracción de Talento y Marca Empleadora | W20: Talento | AB20: FALSE | AC20: FALSE | AE20: FALSE | AG20: FALSE | AI20: FALSE | AK20: Medios Tradicionales | AL20: CREATÓN | AM20: 46266 | AN20: 0.66010417 | AO20: 0 | AP20: Diagonal 23C BIS Transversal 88C-88b, 110911 Bogota, D.C., Colombia | AQ20: DP | AR20: 90.5 | AS20: Cata | AT20: Asuntos Corporativos | AU20: SI | AV20: OK | AW20: =IF(L20="Otra",IF(M20="","Otra",M20&""),L20&"") -> Negocios Internacionales | AX20: =IF(OR(AO20="",AO20=0),"",TRIM(AO20)) | AY20: =IFERROR(INDEX(Vacantes!$C:$C,MATCH(AT20,Vacantes!$A:$A,0)),"") -> 127 | AZ20: =IFERROR(INDEX(Vacantes!$D:$D,MATCH(AT20,Vacantes!$A:$A,0)),"") -> 13 de octubre de 2026 | BA20: =IFERROR(INDEX(Vacantes!$E:$E,MATCH(AT20,Vacantes!$A:$A,0)),"") -> 1:30 p.m. a 5:30 p.m.
A21: dfelipegomeza203@gmail.com | B21: Daniel Gómez Anaya | C21: Cédula de ciudadanía | D21: 1001096590 | E21: Hombre | F21: 23 | G21: TRUE | H21: BOGOTA | I21: Bogotá | J21: Universidad del Rosario | L21: Economía | N21: TRUE | O21: FALSE | P21: Avanzado | Q21: Intermedio | R21: Asuntos corporativos | W21: Compras | AB21: FALSE | AC21: FALSE | AE21: FALSE | AG21: FALSE | AI21: FALSE | AK21: Otros | AL21: CREATÓN | AM21: 46262 | AN21: 0.35939815 | AO21: 302 2508910 | AP21: Carrera 7B 127C-58, 110121 Bogota, D.C., Colombia | AQ21: DP | AR21: 70.1 | AS21: Cata | AT21: Asuntos Corporativos | AU21: SI | AV21: OK | AW21: =IF(L21="Otra",IF(M21="","Otra",M21&""),L21&"") -> Economía | AX21: =IF(OR(AO21="",AO21=0),"",TRIM(AO21)) -> 302 2508910 | AY21: =IFERROR(INDEX(Vacantes!$C:$C,MATCH(AT21,Vacantes!$A:$A,0)),"") -> 127 | AZ21: =IFERROR(INDEX(Vacantes!$D:$D,MATCH(AT21,Vacantes!$A:$A,0)),"") -> 13 de octubre de 2026 | BA21: =IFERROR(INDEX(Vacantes!$E:$E,MATCH(AT21,Vacantes!$A:$A,0)),"") -> 1:30 p.m. a 5:30 p.m.
A22: daza.matias@javeriana.edu.co | B22: Matias Daza | C22: Cédula de ciudadanía | D22: 1031652558 | E22: Hombre | F22: 19 | G22: TRUE | H22: BOGOTA | I22: Bogotá | J22: Pontificia Universidad Javeriana | L22: Derecho | N22: TRUE | O22: FALSE | P22: Avanzado | Q22: Intermedio | R22: Asuntos corporativos | W22: Ventas | AA22: Ventas Comercial | AB22: FALSE | AC22: FALSE | AE22: FALSE | AG22: FALSE | AI22: FALSE | AK22: Instagram | AL22: CREATÓN | AM22: 46277 | AN22: 0.61746528 | AO22: 3058170290 | AP22: Carrera 89 147B-79, 111156 Bogota, D.C., Colombia | AQ22: DP | AR22: 74.1 | AS22: Cata | AT22: Asuntos Corporativos | AU22: SI | AV22: OK | AW22: =IF(L22="Otra",IF(M22="","Otra",M22&""),L22&"") -> Derecho | AX22: =IF(OR(AO22="",AO22=0),"",TRIM(AO22)) -> 3058170290 | AY22: =IFERROR(INDEX(Vacantes!$C:$C,MATCH(AT22,Vacantes!$A:$A,0)),"") -> 127 | AZ22: =IFERROR(INDEX(Vacantes!$D:$D,MATCH(AT22,Vacantes!$A:$A,0)),"") -> 13 de octubre de 2026 | BA22: =IFERROR(INDEX(Vacantes!$E:$E,MATCH(AT22,Vacantes!$A:$A,0)),"") -> 1:30 p.m. a 5:30 p.m.
A23: nicolechiquiza@gmail.com | B23: Nicole Daiam Chiquiza Moreno | C23: Cédula de ciudadanía | D23: 1072644235 | E23: Mujer | F23: 21 | G23: TRUE | H23: CHIA CUNDINAMARCA | I23: Bogotá | J23: Universidad de los Andes | L23: Administración de Empresas | N23: FALSE | O23: FALSE | P23: Intermedio | Q23: Intermedio | R23: Marketing | U23: Atracción de Talento y Marca Empleadora | W23: Talento | AB23: FALSE | AC23: FALSE | AE23: FALSE | AG23: FALSE | AI23: FALSE | AK23: LinkedIn | AL23: CREATÓN | AM23: 46268 | AN23: 0.0018171296 | AO23: 305 3136665 | AP23: Calle 7 1-84, 250001 Chía, Colombia | AQ23: DP | AR23: 83.8 | AS23: Cata | AT23: Atracción de talento y Marca Empleadora | AU23: SI | AV23: OK | AW23: =IF(L23="Otra",IF(M23="","Otra",M23&""),L23&"") -> Administración de Empresas | AX23: =IF(OR(AO23="",AO23=0),"",TRIM(AO23)) -> 305 3136665 | AY23: =IFERROR(INDEX(Vacantes!$C:$C,MATCH(AT23,Vacantes!$A:$A,0)),"") -> 127 | AZ23: =IFERROR(INDEX(Vacantes!$D:$D,MATCH(AT23,Vacantes!$A:$A,0)),"") -> 13 de octubre de 2026 | BA23: =IFERROR(INDEX(Vacantes!$E:$E,MATCH(AT23,Vacantes!$A:$A,0)),"") -> 7:30 a.m. a 11:30 a.m.
A24: gabyaguirrecortes@gmail.com | B24: Gabriela Aguirre Cortes | C24: Cédula de ciudadanía | D24: 1016912331 | E24: Mujer | F24: 21 | G24: TRUE | I24: Bogotá | J24: Universidad Externado de Colombia | L24: Administración de Empresas | N24: FALSE | O24: FALSE | P24: Avanzado | Q24: Avanzado | R24: Marketing | U24: Atracción de Talento y Marca Empleadora | W24: Talento | AB24: FALSE | AC24: FALSE | AE24: FALSE | AG24: FALSE | AI24: FALSE | AK24: Otros | AL24: CREATÓN | AM24: 46256 | AN24: 0.42581019 | AO24: 319 4972788 | AP24: Carrera 73B 146F-25, 111156 Bogota, D.C., Colombia | AQ24: DP | AR24: 85.2 | AS24: Cata | AT24: Atracción de talento y Marca Empleadora | AU24: SI | AV24: OK | AW24: =IF(L24="Otra",IF(M24="","Otra",M24&""),L24&"") -> Administración de Empresas | AX24: =IF(OR(AO24="",AO24=0),"",TRIM(AO24)) -> 319 4972788 | AY24: =IFERROR(INDEX(Vacantes!$C:$C,MATCH(AT24,Vacantes!$A:$A,0)),"") -> 127 | AZ24: =IFERROR(INDEX(Vacantes!$D:$D,MATCH(AT24,Vacantes!$A:$A,0)),"") -> 13 de octubre de 2026 | BA24: =IFERROR(INDEX(Vacantes!$E:$E,MATCH(AT24,Vacantes!$A:$A,0)),"") -> 7:30 a.m. a 11:30 a.m.
A25: foreroandres292@gmail.com | B25: Andres Fuentes Forero | C25: Cédula de ciudadanía | D25: 1000286128 | E25: Hombre | F25: 23 | G25: TRUE | I25: Bogotá | J25: Universidad del Rosario | L25: Negocios Internacionales | N25: FALSE | O25: FALSE | P25: Avanzado | Q25: Intermedio | R25: Logística | U25: Atracción de Talento y Marca Empleadora | W25: Talento | AB25: FALSE | AC25: FALSE | AE25: FALSE | AG25: FALSE | AI25: FALSE | AK25: Instagram | AL25: CREATÓN | AM25: 46255 | AN25: 0.4146875 | AO25: 318 2479065 | AP25: Calle 53 4A-69, 110231 Bogota, D.C., Colombia | AQ25: DP | AR25: 81.9 | AS25: Cata | AT25: Atracción de talento y Marca Empleadora | AU25: SI | AV25: OK | AW25: =IF(L25="Otra",IF(M25="","Otra",M25&""),L25&"") -> Negocios Internacionales | AX25: =IF(OR(AO25="",AO25=0),"",TRIM(AO25)) -> 318 2479065 | AY25: =IFERROR(INDEX(Vacantes!$C:$C,MATCH(AT25,Vacantes!$A:$A,0)),"") -> 127 | AZ25: =IFERROR(INDEX(Vacantes!$D:$D,MATCH(AT25,Vacantes!$A:$A,0)),"") -> 13 de octubre de 2026 | BA25: =IFERROR(INDEX(Vacantes!$E:$E,MATCH(AT25,Vacantes!$A:$A,0)),"") -> 7:30 a.m. a 11:30 a.m.
A26: sarahernandezn.20@gmail.com | B26: Sara Sofia Hernandez Neira | C26: Cédula de ciudadanía | D26: 1021512114 | E26: Mujer | F26: 22 | G26: TRUE | H26: Bogotá | I26: Bogotá | J26: Universidad de La Sabana | L26: Negocios Internacionales | N26: FALSE | O26: FALSE | P26: Avanzado | Q26: Avanzado | R26: Talento | W26: Ventas | Z26: Atracción de Talento y Marca Empleadora | AA26: Gestión de Ejecución Premium | AB26: FALSE | AC26: FALSE | AE26: FALSE | AG26: FALSE | AI26: FALSE | AK26: Instagram | AL26: CREATÓN | AM26: 46259 | AN26: 0.81193287 | AO26: 313 4649889 | AP26: Carrera 62 165A-69, 111156 Bogota, D.C., Colombia | AQ26: DP | AR26: 80.5 | AS26: Cata | AT26: Atracción de talento y Marca Empleadora | AU26: SI | AV26: OK | AW26: =IF(L26="Otra",IF(M26="","Otra",M26&""),L26&"") -> Negocios Internacionales | AX26: =IF(OR(AO26="",AO26=0),"",TRIM(AO26)) -> 313 4649889 | AY26: =IFERROR(INDEX(Vacantes!$C:$C,MATCH(AT26,Vacantes!$A:$A,0)),"") -> 127 | AZ26: =IFERROR(INDEX(Vacantes!$D:$D,MATCH(AT26,Vacantes!$A:$A,0)),"") -> 13 de octubre de 2026 | BA26: =IFERROR(INDEX(Vacantes!$E:$E,MATCH(AT26,Vacantes!$A:$A,0)),"") -> 7:30 a.m. a 11:30 a.m.
A27: mariacasjau@unisabana.edu.co | B27: Maria Alejandra Castro Jauregui | C27: Cédula de ciudadanía | D27: 1012337267 | E27: Mujer | F27: 20 | G27: TRUE | H27: Bogotá | I27: Bogotá | J27: Universidad de La Sabana | L27: Psicología | N27: FALSE | O27: FALSE | P27: Avanzado | Q27: Intermedio | R27: Talento | W27: Comunicaciones | Z27: Atracción de Talento y Marca Empleadora | AB27: FALSE | AC27: TRUE | AE27: FALSE | AG27: FALSE | AH27: Padre - William Humberto Castro Riaño | AI27: FALSE | AK27: Instagram | AL27: CREATÓN | AM27: 46265 | AN27: 0.45572917 | AO27: 322 4018881 | AP27: Carrera 53 141-69, 111156 Bogota, D.C., Colombia | AQ27: DP | AR27: 88.2 | AS27: Cata | AT27: Atracción de talento y Marca Empleadora | AU27: SI | AV27: OK | AW27: =IF(L27="Otra",IF(M27="","Otra",M27&""),L27&"") -> Psicología | AX27: =IF(OR(AO27="",AO27=0),"",TRIM(AO27)) -> 322 4018881 | AY27: =IFERROR(INDEX(Vacantes!$C:$C,MATCH(AT27,Vacantes!$A:$A,0)),"") -> 127 | AZ27: =IFERROR(INDEX(Vacantes!$D:$D,MATCH(AT27,Vacantes!$A:$A,0)),"") -> 13 de octubre de 2026 | BA27: =IFERROR(INDEX(Vacantes!$E:$E,MATCH(AT27,Vacantes!$A:$A,0)),"") -> 7:30 a.m. a 11:30 a.m.
A28: c.gomezt2@uniandes.edu.co | B28: Catalina Gómez | C28: Cédula de ciudadanía | D28: 1107834811 | E28: Mujer | F28: 22 | G28: TRUE | H28: BOGOTA | I28: Bogotá | J28: Universidad de los Andes | L28: Administración de Empresas | N28: FALSE | O28: FALSE | P28: Avanzado | Q28: Avanzado | R28: Ventas | V28: Talento Ventas | W28: Marketing | AB28: FALSE | AC28: FALSE | AE28: FALSE | AG28: FALSE | AI28: FALSE | AK28: LinkedIn | AL28: CREATÓN | AM28: 46269 | AN28: 0.24943287 | AO28: 3116257553 | AP28: Calle 70A 7-36, 110231 Bogota, D.C., Colombia | AQ28: DP | AR28: 98.3 | AS28: Cata | AT28: Atracción de talento y Marca Empleadora | AU28: SI | AV28: OK | AW28: =IF(L28="Otra",IF(M28="","Otra",M28&""),L28&"") -> Administración de Empresas | AX28: =IF(OR(AO28="",AO28=0),"",TRIM(AO28)) -> 3116257553 | AY28: =IFERROR(INDEX(Vacantes!$C:$C,MATCH(AT28,Vacantes!$A:$A,0)),"") -> 127 | AZ28: =IFERROR(INDEX(Vacantes!$D:$D,MATCH(AT28,Vacantes!$A:$A,0)),"") -> 13 de octubre de 2026 | BA28: =IFERROR(INDEX(Vacantes!$E:$E,MATCH(AT28,Vacantes!$A:$A,0)),"") -> 7:30 a.m. a 11:30 a.m.
A29: marianaroro16@gmail.com | B29: Mariana Rojas Rodriguez | C29: Cédula de ciudadanía | D29: 1023372804 | E29: Mujer | F29: 20 | G29: TRUE | H29: BOGOTÁ D.C | I29: Bogotá | J29: Universidad Piloto de Colombia | L29: Psicología | N29: TRUE | O29: FALSE | P29: Intermedio | Q29: Intermedio | R29: Talento | W29: Marketing | Z29: Atracción de Talento y Marca Empleadora | AB29: FALSE | AC29: FALSE | AE29: FALSE | AG29: FALSE | AI29: FALSE | AK29: LinkedIn | AL29: CREATÓN | AM29: 46262 | AN29: 0.24175926 | AO29: 305 7325384 | AP29: Calle 56A Sur 72C-10, 110741 Bogota, D.C., Colombia | AQ29: DP | AR29: 86.2 | AS29: Cata | AT29: Atracción de talento y Marca Empleadora | AU29: SI | AV29: OK | AW29: =IF(L29="Otra",IF(M29="","Otra",M29&""),L29&"") -> Psicología | AX29: =IF(OR(AO29="",AO29=0),"",TRIM(AO29)) -> 305 7325384 | AY29: =IFERROR(INDEX(Vacantes!$C:$C,MATCH(AT29,Vacantes!$A:$A,0)),"") -> 127 | AZ29: =IFERROR(INDEX(Vacantes!$D:$D,MATCH(AT29,Vacantes!$A:$A,0)),"") -> 13 de octubre de 2026 | BA29: =IFERROR(INDEX(Vacantes!$E:$E,MATCH(AT29,Vacantes!$A:$A,0)),"") -> 7:30 a.m. a 11:30 a.m.
A30: gabilievano0120@gmail.com | B30: Gabriela Lievano | C30: Cédula de ciudadanía | D30: 1031610059 | E30: Mujer | F30: 22 | G30: TRUE | H30: Bogotá, D.C. | I30: Bogotá | J30: Universidad de los Andes | L30: Administración de Empresas | N30: FALSE | O30: FALSE | P30: Avanzado | Q30: Avanzado | R30: Talento | W30: Marketing | Z30: Atracción de Talento y Marca Empleadora | AB30: FALSE | AC30: FALSE | AE30: FALSE | AG30: FALSE | AI30: FALSE | AK30: LinkedIn | AL30: CREATÓN | AM30: 46266 | AN30: 0.68083333 | AO30: 3107579299 | AP30: Los Rosales, Bogota, D.C., Colombia | AQ30: DP | AR30: 93.4 | AS30: Santi | AT30: Atracción de talento y Marca Empleadora | AU30: SI | AV30: OK | AW30: =IF(L30="Otra",IF(M30="","Otra",M30&""),L30&"") -> Administración de Empresas | AX30: =IF(OR(AO30="",AO30=0),"",TRIM(AO30)) -> 3107579299 | AY30: =IFERROR(INDEX(Vacantes!$C:$C,MATCH(AT30,Vacantes!$A:$A,0)),"") -> 127 | AZ30: =IFERROR(INDEX(Vacantes!$D:$D,MATCH(AT30,Vacantes!$A:$A,0)),"") -> 13 de octubre de 2026 | BA30: =IFERROR(INDEX(Vacantes!$E:$E,MATCH(AT30,Vacantes!$A:$A,0)),"") -> 7:30 a.m. a 11:30 a.m.
A31: alejandraparracard@gmail.com | B31: María Alejandra Parra Cárdenas | C31: Cédula de ciudadanía | D31: 1011090066 | E31: Mujer | F31: 20 | G31: TRUE | I31: Bogotá | J31: Universidad Externado de Colombia | L31: Finanzas | N31: FALSE | O31: FALSE | P31: Intermedio | Q31: Intermedio | R31: Ventas | V31: Canal Moderno | W31: Marketing | AB31: FALSE | AC31: FALSE | AE31: FALSE | AG31: FALSE | AI31: FALSE | AK31: Instagram | AL31: CREATÓN | AM31: 46273 | AN31: 0.26524306 | AO31: 321 9095151 | AP31: Calle 66C 61-1, 111221 Bogota, D.C., Colombia | AQ31: DP | AR31: 96.4 | AS31: Cata | AT31: Canal moderno (KA) | AU31: SI | AV31: OK | AW31: =IF(L31="Otra",IF(M31="","Otra",M31&""),L31&"") -> Finanzas | AX31: =IF(OR(AO31="",AO31=0),"",TRIM(AO31)) -> 321 9095151 | AY31: =IFERROR(INDEX(Vacantes!$C:$C,MATCH(AT31,Vacantes!$A:$A,0)),"") -> 127 | AZ31: =IFERROR(INDEX(Vacantes!$D:$D,MATCH(AT31,Vacantes!$A:$A,0)),"") -> 13 de octubre de 2026 | BA31: =IFERROR(INDEX(Vacantes!$E:$E,MATCH(AT31,Vacantes!$A:$A,0)),"") -> 1:30 p.m. a 5:30 p.m.
A32: ignacio.vega.gouffray@gmail.com | B32: Hernando Ignacio Vega Gouffray | C32: Cédula de ciudadanía | D32: 1000503044 | E32: Hombre | F32: 23 | G32: TRUE | H32: Bogotá | I32: Bogotá | J32: Pontificia Universidad Javeriana | L32: Ingeniería Industrial | N32: FALSE | O32: FALSE | P32: Avanzado | Q32: Avanzado | R32: Ventas | V32: Ventas Comercial | W32: Ventas | AA32: Canal Moderno | AB32: FALSE | AC32: FALSE | AE32: FALSE | AG32: FALSE | AI32: FALSE | AK32: LinkedIn | AL32: CREATÓN | AM32: 46259 | AN32: 0.55434028 | AO32: 316 6197879 | AP32: Edificio Palo Alto, 110221 Bogota, D.C., Colombia | AQ32: DP | AR32: 76.7 | AS32: Cata | AT32: Canal moderno (KA) | AU32: SI | AV32: OK | AW32: =IF(L32="Otra",IF(M32="","Otra",M32&""),L32&"") -> Ingeniería Industrial | AX32: =IF(OR(AO32="",AO32=0),"",TRIM(AO32)) -> 316 6197879 | AY32: =IFERROR(INDEX(Vacantes!$C:$C,MATCH(AT32,Vacantes!$A:$A,0)),"") -> 127 | AZ32: =IFERROR(INDEX(Vacantes!$D:$D,MATCH(AT32,Vacantes!$A:$A,0)),"") -> 13 de octubre de 2026 | BA32: =IFERROR(INDEX(Vacantes!$E:$E,MATCH(AT32,Vacantes!$A:$A,0)),"") -> 1:30 p.m. a 5:30 p.m.
A33: danigalan1805@gmail.com | B33: Daniela Galán Muñoz | C33: Cédula de ciudadanía | D33: 1051066730 | E33: Mujer | F33: 20 | G33: TRUE | I33: Bogotá | J33: Otra | K33: Universidad de Boyacá | L33: Ingeniería Industrial | N33: TRUE | O33: FALSE | P33: Intermedio | Q33: Intermedio | R33: Logística | W33: Ventas | AA33: Canal Moderno | AB33: FALSE | AC33: FALSE | AE33: FALSE | AG33: FALSE | AI33: FALSE | AK33: Página Web Oficial | AL33: CREATÓN | AM33: 46255 | AN33: 0.41467593 | AO33: 322 9448422 | AP33: Paipa, Colombia | AQ33: DP | AR33: 93.9 | AS33: Cata | AT33: Canal moderno (KA) | AU33: SI | AV33: OK | AW33: =IF(L33="Otra",IF(M33="","Otra",M33&""),L33&"") -> Ingeniería Industrial | AX33: =IF(OR(AO33="",AO33=0),"",TRIM(AO33)) -> 322 9448422 | AY33: =IFERROR(INDEX(Vacantes!$C:$C,MATCH(AT33,Vacantes!$A:$A,0)),"") -> 127 | AZ33: =IFERROR(INDEX(Vacantes!$D:$D,MATCH(AT33,Vacantes!$A:$A,0)),"") -> 13 de octubre de 2026 | BA33: =IFERROR(INDEX(Vacantes!$E:$E,MATCH(AT33,Vacantes!$A:$A,0)),"") -> 1:30 p.m. a 5:30 p.m.
A34: valeriarojasmora2@gmail.com | B34: Valeria Rojas Mora | C34: Cédula de ciudadanía | D34: 1031809430 | E34: Mujer | F34: 19 | G34: TRUE | H34: BOGOTÁ | I34: Bogotá | J34: Universidad del Bosque | L34: Negocios Internacionales | N34: FALSE | O34: FALSE | P34: Avanzado | Q34: Intermedio | R34: Ventas | V34: Talento Ventas | W34: Marketing | AB34: FALSE | AC34: FALSE | AE34: FALSE | AG34: FALSE | AI34: FALSE | AK34: LinkedIn | AL34: CREATÓN | AM34: 46267 | AN34: 0.55072917 | AO34: 322 2237039 | AP34: Calle 151B 102B-90, 111161 Bogota, D.C., Colombia | AQ34: DP | AR34: 91.5 | AS34: Santi | AT34: Canal moderno (KA) | AU34: SI | AV34: OK | AW34: =IF(L34="Otra",IF(M34="","Otra",M34&""),L34&"") -> Negocios Internacionales | AX34: =IF(OR(AO34="",AO34=0),"",TRIM(AO34)) -> 322 2237039 | AY34: =IFERROR(INDEX(Vacantes!$C:$C,MATCH(AT34,Vacantes!$A:$A,0)),"") -> 127 | AZ34: =IFERROR(INDEX(Vacantes!$D:$D,MATCH(AT34,Vacantes!$A:$A,0)),"") -> 13 de octubre de 2026 | BA34: =IFERROR(INDEX(Vacantes!$E:$E,MATCH(AT34,Vacantes!$A:$A,0)),"") -> 1:30 p.m. a 5:30 p.m.
A35: erikacure12@gmail.com | B35: Erika Cure | C35: Cédula de ciudadanía | D35: 1042243518 | E35: Mujer | F35: 21 | G35: TRUE | H35: BOGOTA | I35: Bogotá | J35: Colegio de Estudios Superiores de Administración CESA | L35: Administración de Empresas | N35: TRUE | O35: FALSE | P35: Avanzado | Q35: Avanzado | R35: Marketing | W35: Ventas | AA35: Canal Moderno | AB35: FALSE | AC35: FALSE | AE35: FALSE | AG35: FALSE | AI35: FALSE | AK35: Otros | AL35: CREATÓN | AM35: 46277 | AN35: 0.6271412 | AO35: 321 7794626 | AP35: Calle 72A 0-54, 110221 Bogota, D.C., Colombia | AQ35: DP | AR35: 71.3 | AS35: Cata | AT35: Canal moderno (KA) | AU35: SI | AV35: OK | AW35: =IF(L35="Otra",IF(M35="","Otra",M35&""),L35&"") -> Administración de Empresas | AX35: =IF(OR(AO35="",AO35=0),"",TRIM(AO35)) -> 321 7794626 | AY35: =IFERROR(INDEX(Vacantes!$C:$C,MATCH(AT35,Vacantes!$A:$A,0)),"") -> 127 | AZ35: =IFERROR(INDEX(Vacantes!$D:$D,MATCH(AT35,Vacantes!$A:$A,0)),"") -> 13 de octubre de 2026 | BA35: =IFERROR(INDEX(Vacantes!$E:$E,MATCH(AT35,Vacantes!$A:$A,0)),"") -> 1:30 p.m. a 5:30 p.m.
A36: natalia.lizarazo.lopez@gmail.com | B36: Natalia Lizarazo | C36: Cédula de ciudadanía | D36: 1034399810 | E36: Mujer | F36: 20 | G36: TRUE | I36: Bogotá | J36: Escuela Colombiana de Ingeniería Julio Garavito | L36: Ingeniería Industrial | N36: TRUE | O36: FALSE | P36: Intermedio | Q36: Básico | R36: Logística | W36: Ventas | AA36: BEES | AB36: FALSE | AC36: FALSE | AE36: FALSE | AG36: FALSE | AI36: FALSE | AK36: Instagram | AL36: CREATÓN | AM36: 46257 | AN36: 0.77711806 | AO36: 0 | AP36: Calle 75A 76-58, 111051 Bogota, D.C., Colombia | AQ36: DP | AR36: 89.8 | AS36: Santi | AT36: Channel Strategy and Performance (BEES) | AU36: SI | AV36: OK | AW36: =IF(L36="Otra",IF(M36="","Otra",M36&""),L36&"") -> Ingeniería Industrial | AX36: =IF(OR(AO36="",AO36=0),"",TRIM(AO36)) | AY36: =IFERROR(INDEX(Vacantes!$C:$C,MATCH(AT36,Vacantes!$A:$A,0)),"") -> 127 | AZ36: =IFERROR(INDEX(Vacantes!$D:$D,MATCH(AT36,Vacantes!$A:$A,0)),"") -> 13 de octubre de 2026 | BA36: =IFERROR(INDEX(Vacantes!$E:$E,MATCH(AT36,Vacantes!$A:$A,0)),"") -> 1:30 p.m. a 5:30 p.m.
A37: douglas.plazasg@gmail.com | B37: Douglas Plazas Guzman | C37: Cédula de ciudadanía | D37: 1000502600 | E37: Hombre | F37: 24 | G37: TRUE | I37: Bogotá | J37: Universidad de los Andes | L37: Economía | N37: FALSE | O37: FALSE | P37: Avanzado | Q37: Avanzado | R37: Ventas | V37: Gestión de Ejecución Premium | W37: Logística | AB37: FALSE | AC37: FALSE | AE37: FALSE | AG37: FALSE | AI37: FALSE | AK37: Instagram | AL37: CREATÓN | AM37: 46256 | AN37: 0.65561343 | AO37: 310 4683903 | AP37: Bogota, D.C., Colombia | AQ37: DP | AR37: 91 | AS37: Cata | AT37: Channel Strategy and Performance (BEES) | AU37: SI | AV37: OK | AW37: =IF(L37="Otra",IF(M37="","Otra",M37&""),L37&"") -> Economía | AX37: =IF(OR(AO37="",AO37=0),"",TRIM(AO37)) -> 310 4683903 | AY37: =IFERROR(INDEX(Vacantes!$C:$C,MATCH(AT37,Vacantes!$A:$A,0)),"") -> 127 | AZ37: =IFERROR(INDEX(Vacantes!$D:$D,MATCH(AT37,Vacantes!$A:$A,0)),"") -> 13 de octubre de 2026 | BA37: =IFERROR(INDEX(Vacantes!$E:$E,MATCH(AT37,Vacantes!$A:$A,0)),"") -> 1:30 p.m. a 5:30 p.m.
A38: isabellaforero0210@outlook.com | B38: Isabella Forero | C38: Cédula de ciudadanía | D38: 1001191913 | E38: Mujer | F38: 22 | G38: TRUE | H38: BOGOTA | I38: Bogotá | J38: Universidad del Rosario | L38: Marketing / Mercadeo | N38: FALSE | O38: FALSE | P38: Avanzado | Q38: Intermedio | R38: Marketing | W38: Ventas | AA38: BEES | AB38: FALSE | AC38: FALSE | AE38: FALSE | AG38: FALSE | AI38: FALSE | AK38: Página Web Oficial | AL38: CREATÓN | AM38: 46271 | AN38: 0.72023148 | AO38: 304 4266492 | AP38: Calle 114A 19A-67, 110111 Bogota, D.C., Colombia | AQ38: DP | AR38: 92.3 | AS38: Cata | AT38: Channel Strategy and Performance (BEES) | AU38: SI | AV38: OK | AW38: =IF(L38="Otra",IF(M38="","Otra",M38&""),L38&"") -> Marketing / Mercadeo | AX38: =IF(OR(AO38="",AO38=0),"",TRIM(AO38)) -> 304 4266492 | AY38: =IFERROR(INDEX(Vacantes!$C:$C,MATCH(AT38,Vacantes!$A:$A,0)),"") -> 127 | AZ38: =IFERROR(INDEX(Vacantes!$D:$D,MATCH(AT38,Vacantes!$A:$A,0)),"") -> 13 de octubre de 2026 | BA38: =IFERROR(INDEX(Vacantes!$E:$E,MATCH(AT38,Vacantes!$A:$A,0)),"") -> 1:30 p.m. a 5:30 p.m.
A39: daniel.felipe.ladino@gmail.com | B39: Daniel Felipe Ladino Torres | C39: Cédula de ciudadanía | D39: 1000796156 | E39: Hombre | F39: 23 | G39: TRUE | H39: Bogota | I39: Bogotá | J39: Universidad Externado de Colombia | L39: Administración de Empresas | N39: FALSE | O39: FALSE | P39: Intermedio | Q39: Intermedio | R39: Marketing | W39: Ventas | AA39: BEES | AB39: FALSE | AC39: FALSE | AE39: FALSE | AG39: FALSE | AI39: FALSE | AK39: Otros | AL39: CREATÓN | AM39: 46266 | AN39: 0.36131944 | AO39: 3175756956 | AP39: Carrera 74A 168A-50, 111156 Bogota, D.C., Colombia | AQ39: DP | AR39: 75.2 | AS39: Cata | AT39: Channel Strategy and Performance (BEES) | AU39: SI | AV39: OK | AW39: =IF(L39="Otra",IF(M39="","Otra",M39&""),L39&"") -> Administración de Empresas | AX39: =IF(OR(AO39="",AO39=0),"",TRIM(AO39)) -> 3175756956 | AY39: =IFERROR(INDEX(Vacantes!$C:$C,MATCH(AT39,Vacantes!$A:$A,0)),"") -> 127 | AZ39: =IFERROR(INDEX(Vacantes!$D:$D,MATCH(AT39,Vacantes!$A:$A,0)),"") -> 13 de octubre de 2026 | BA39: =IFERROR(INDEX(Vacantes!$E:$E,MATCH(AT39,Vacantes!$A:$A,0)),"") -> 1:30 p.m. a 5:30 p.m.
A40: cataochoad300@gmail.com | B40: Catalina Ochoa Dueñas | C40: Cédula de ciudadanía | D40: 1025061418 | E40: Mujer | F40: 21 | G40: TRUE | H40: BOGOTA | I40: Bogotá | J40: Universidad Externado de Colombia | L40: Administración de Empresas | N40: FALSE | O40: FALSE | P40: Intermedio | Q40: Avanzado | R40: Ventas | V40: BEES | W40: Ventas | AA40: Talento Ventas | AB40: FALSE | AC40: FALSE | AE40: FALSE | AG40: FALSE | AI40: FALSE | AK40: Otros | AL40: CREATÓN | AM40: 46271 | AN40: 0.72021991 | AO40: 322 2444642 | AP40: Calle 45-16, 111321 Bogota, D.C., Colombia | AQ40: DP | AR40: 81.1 | AS40: Cata | AT40: Channel Strategy and Performance (BEES) | AU40: SI | AV40: OK | AW40: =IF(L40="Otra",IF(M40="","Otra",M40&""),L40&"") -> Administración de Empresas | AX40: =IF(OR(AO40="",AO40=0),"",TRIM(AO40)) -> 322 2444642 | AY40: =IFERROR(INDEX(Vacantes!$C:$C,MATCH(AT40,Vacantes!$A:$A,0)),"") -> 127 | AZ40: =IFERROR(INDEX(Vacantes!$D:$D,MATCH(AT40,Vacantes!$A:$A,0)),"") -> 13 de octubre de 2026 | BA40: =IFERROR(INDEX(Vacantes!$E:$E,MATCH(AT40,Vacantes!$A:$A,0)),"") -> 1:30 p.m. a 5:30 p.m.
...

Sheet Vacantes
A1: Vacante | B1: Ubicación / Planta (funnel) | C1: Site | D1: Fecha creatón | E1: Horario creatón | F1: Fecha creatón (texto original)
A2: Area financiera (PPM) | B2: 127 | C2: 127 | D2: 13 de octubre de 2026 | E2: 7:30 a.m. a 11:30 a.m. | F2: 13 de octubre de 2026, 7:30 a.m. a 11:30 a.m.
A3: Asuntos Corporativos | B3: 127 | C3: 127 | D3: 13 de octubre de 2026 | E3: 1:30 p.m. a 5:30 p.m. | F3: 13 de octubre de 2026, 1:30 p.m. a 5:30 p.m.
A4: Atracción de talento y Marca Empleadora | B4: 127 | C4: 127 | D4: 13 de octubre de 2026 | E4: 7:30 a.m. a 11:30 a.m. | F4: 13 de octubre de 2026, 7:30 a.m. a 11:30 a.m.
A5: Canal moderno (KA) | B5: 127 | C5: 127 | D5: 13 de octubre de 2026 | E5: 1:30 p.m. a 5:30 p.m. | F5: 13 de octubre de 2026, 1:30 p.m. a 5:30 p.m.
A6: Channel Strategy and Performance (BEES) | B6: 127 | C6: 127 | D6: 13 de octubre de 2026 | E6: 1:30 p.m. a 5:30 p.m. | F6: 13 de octubre de 2026, 1:30 p.m. a 5:30 p.m.
A7: Compensación y beneficios | B7: 127 | C7: 127 | D7: 13 de octubre de 2026 | E7: 7:30 a.m. a 11:30 a.m. | F7: 13 de octubre de 2026, 7:30 a.m. a 11:30 a.m.
A8: Compras (Procurement PPM Reporting) | B8: 127 | C8: 127 | D8: 13 de octubre de 2026 | E8: 7:30 a.m. a 11:30 a.m. | F8: 13 de octubre de 2026, 7:30 a.m. a 11:30 a.m.
A9: Comunicaciones | B9: 127 | C9: 127 | D9: 13 de octubre de 2026 | E9: 1:30 p.m. a 5:30 p.m. | F9: 13 de octubre de 2026, 1:30 p.m. a 5:30 p.m.
A10: Finanzas Control Interno | B10: 127 | C10: 127 | D10: No aplica (vacante a 1 año) | E10: No aplica (vacante a 1 año) | F10: No aplica (vacante a 1 año)
A11: Gestión de talento | B11: 127 | C11: 127 | D11: No aplica (vacante a 1 año) | E11: No aplica (vacante a 1 año) | F11: No aplica (vacante a 1 año)
A12: Logística T2 (Safety & DPO T2) | B12: 127/Regional Centro | C12: 127 | D12: 13 de octubre de 2026 | E12: 7:30 a.m. a 11:30 a.m. | F12: 13 de octubre de 2026, 7:30 a.m. a 11:30 a.m.
A13: MKT Balance choice | B13: 127 | C13: 127 | D13: 16 de octubre de 2026 | E13: 1:30 p.m. a 3:30 p.m. | F13: 16 de octubre de 2026, 1:30 p.m. a 3:30 p.m.
A14: MKT Core brands | B14: 127 | C14: 127 | D14: 16 de octubre de 2026 | E14: 1:30 p.m. a 3:30 p.m. | F14: 16 de octubre de 2026, 1:30 p.m. a 3:30 p.m.
A15: MKT High end | B15: 127 | C15: 127 | D15: 16 de octubre de 2026 | E15: 1:30 p.m. a 3:30 p.m. | F15: 16 de octubre de 2026, 1:30 p.m. a 3:30 p.m.
A16: MKT Premium brands | B16: 127 | C16: 127 | D16: 16 de octubre de 2026 | E16: 1:30 p.m. a 3:30 p.m. | F16: 16 de octubre de 2026, 1:30 p.m. a 3:30 p.m.
A17: People Support 1 | B17: 127 | C17: 127 | D17: 13 de octubre de 2026 | E17: 7:30 a.m. a 11:30 a.m. | F17: 13 de octubre de 2026, 7:30 a.m. a 11:30 a.m.
A18: People Support 2 | B18: 127 | C18: 127 | D18: 13 de octubre de 2026 | E18: 1:30 p.m. a 5:30 p.m. | F18: 13 de octubre de 2026, 1:30 p.m. a 5:30 p.m.
A19: Relaciones laborales | B19: 127 | C19: 127 | D19: Por confirmar | E19: Por confirmar | F19: Por confirmar
A20: TEV Transporte T1 | B20: Planta Tocancipá | C20: Cervecería de Tocancipá | D20: 27 de octubre de 2026 | E20: 12:30 p.m. a 4:00 p.m. | F20: 27 de octubre de 2026, 12:30 p.m. a 4:00 p.m.
A21: Tecnología (JR Data Scientist) | B21: 127 | C21: 127 | D21: 13 de octubre de 2026 | E21: 7:30 a.m. a 11:30 a.m. | F21: 13 de octubre de 2026, 7:30 a.m. a 11:30 a.m.
A22: Producción (operaciones) Atlantico Envase | B22: Planta Atlantico | C22: Cervecería de Atlántico | D22: 23 de octubre de 2026 | E22: 8:30 a.m. a 12:00 p.m. | F22: 23 de octubre de 2026, 8:30 a.m. a 12:00 p.m.
A23: Producción (operaciones) Atlantico Gestión | B23: Planta Atlantico | C23: Cervecería de Atlántico | D23: 23 de octubre de 2026 | E23: 8:30 a.m. a 12:00 p.m. | F23: 23 de octubre de 2026, 8:30 a.m. a 12:00 p.m.
A24: Brewing & Quality Cervecería de Barranquilla | B24: Planta Barranquilla | C24: Cervecería de Barranquilla | D24: 22 de octubre de 2026 | E24: 12:30 p.m. a 5:00 p.m. | F24: 22 de octubre de 2026, 12:30 p.m. a 5:00 p.m.
A25: Envase Cervecería de Barranquilla | B25: Planta Barranquilla | C25: Cervecería de Barranquilla | D25: 22 de octubre de 2026 | E25: 12:30 p.m. a 5:00 p.m. | F25: 22 de octubre de 2026, 12:30 p.m. a 5:00 p.m.
A26: I&S Cervecería de Barranquilla | B26: Planta Barranquilla | C26: Cervecería de Barranquilla | D26: 22 de octubre de 2026 | E26: 12:30 p.m. a 5:00 p.m. | F26: 22 de octubre de 2026, 12:30 p.m. a 5:00 p.m.
A27: Talento Supply Cervecería de Barranquilla | B27: Planta Barranquilla | C27: Cervecería de Barranquilla | D27: 22 de octubre de 2026 | E27: 12:30 p.m. a 5:00 p.m. | F27: 22 de octubre de 2026, 12:30 p.m. a 5:00 p.m.
A28: Elaboración Boyacá Cervecería de Boyacá | B28: Planta Boyacá | C28: Cervecería de Boyacá | D28: 20 de octubre de 2026 | E28: 7:30 a.m. a 12:00 p.m. | F28: 20 de octubre de 2026, 7:30 a.m. a 12:00 p.m.
A29: Talento Cervecería de Boyacá | B29: Planta Boyacá | C29: Cervecería de Boyacá | D29: 20 de octubre de 2026 | E29: 7:30 a.m. a 12:00 p.m. | F29: 20 de octubre de 2026, 7:30 a.m. a 12:00 p.m.
A30: Producción (operaciones) Bucaramanga | B30: Planta Bucaramanga | C30: Cervecería de Bucaramanga | D30: 21 de octubre de 2026 | E30: 7:30 a.m. a 12:00 p.m. | F30: 21 de octubre de 2026, 7:30 a.m. a 12:00 p.m.
A31: Talento Supply Bucaramanga | B31: Planta Bucaramanga | C31: Cervecería de Bucaramanga | D31: 21 de octubre de 2026 | E31: 7:30 a.m. a 12:00 p.m. | F31: 21 de octubre de 2026, 7:30 a.m. a 12:00 p.m.
A32: Elaboración Cervecería de Medellín | B32: Planta Medellín | C32: Cervecería de Medellín | D32: 21 de octubre de 2026 | E32: 12:30 p.m. a 4:30 p.m. | F32: 21 de octubre de 2026, 12:30 p.m. a 4:30 p.m.
A33: Envase Cervecería de Medellín (Tienen practicante de un año) | B33: Planta Medellín | C33: Cervecería de Medellín | D33: Por confirmar | E33: Por confirmar | F33: Por confirmar
... A55: Ventas Regional Sur | B55: Regional Sur | C55: Regional Sur | D55: 22 de octubre de 2026 | E55: 8:30 a.m. a 12:00 p.m. | F55: 22 de octubre de 2026, 8:30 a.m. a 12:00 p.m.
A57: Nota: Site, Fecha y Horario de la Maestra se buscan aquí por "Vacante sugerida". Si cambia la fecha u horario de una vacante, edítalo en esta hoja y actualiza las tablas dinámicas (Datos > Actualizar todo).
A58: Relaciones laborales queda "Por confirmar" por indicación de TA. Filas en naranja en la Maestra = vacante asignada en esta actualización.

Sheet 127 - R.CENTRO
A1: Candidatos confirmados a la Creatón — 127, Regional Centro
A6: #VALUE!
A49: MKT High end | B49: 1014977540 | C49: Daniela Prado Sahab

Sheet INDUGRAL
A1: Candidatos confirmados a la Creatón — Indugral
A3: Site | B3: Indugral
A4: Confirmación | B4: SI
A6: Vacante | B6: Cédula | C6: Nombre del candidato | D6: Correo | E6: Teléfono contacto | F6: Carrera | G6: Fecha creatón | H6: Horario creatón
A7: Calidad Supply Indugral | B7: 1004419222 | C7: PAULA CAMILA ORTIZ GALINDEZ | D7: cami188ortiz@gmail.com | E7: 317 1662760 | F7: Química | G7: 15 de octubre de 2026 | H7: 12:30 p.m. a 4:00 p.m.
A8: Calidad Supply Indugral | B8: 1005784074 | C8: Natalia Osorio Henao | D8: nataliahenao0527@gmail.com | E8: 300 5568536 | F8: Ingeniería Química | G8: 15 de octubre de 2026 | H8: 12:30 p.m. a 4:00 p.m.
A9: Calidad Supply Indugral | B9: 1006053135 | C9: Brandon Steven Ocampo López | D9: ocampob2003@gmail.com | E9: 318 5139065 | F9: Ingeniería Química | G9: 15 de octubre de 2026 | H9: 12:30 p.m. a 4:00 p.m.
A10: Calidad Supply Indugral | B10: 1083752386 | C10: Nathalia Stephanie Caez Daza | D10: nathalia.caez@correounivalle.edu.co | E10: 300 7487102 | F10: Ingeniería Química | G10: 15 de octubre de 2026 | H10: 12:30 p.m. a 4:00 p.m.
A11: Calidad Supply Indugral | B11: 1085896222 | C11: Juan Coral Tulcan | D11: coraltulcanjuancarlos@gmail.com | E11: 318 4101038 | F11: INGENIERIA EN AUTOMATICA INDUSTRIAL | G11: 15 de octubre de 2026 | H11: 12:30 p.m. a 4:00 p.m.
A12: Calidad Supply Indugral | B12: 1109665069 | C12: Nicol Dayan Pinzón Astaiza | D12: nicold.astaiza@gmail.com | E12: 3144784547 | F12: Ingeniería Industrial | G12: 15 de octubre de 2026 | H12: 12:30 p.m. a 4:00 p.m.
A13: Calidad Supply Indugral | B13: 1110283459 | C13: LINA GISELLE JARAMILLO ORTIZ | D13: lina.giselle.jaramillo@correounivalle.edu.co | E13: 320 2205129 | F13: Química | G13: 15 de octubre de 2026 | H13: 12:30 p.m. a 4:00 p.m.
A14: Calidad Supply Indugral | B14: 1117013881 | C14: Laura Sofía Garcia Patiño | D14: garcialaurasofia0@gmail.com | E14: 322 6378982 | F14: Ingeniería Química | G14: 15 de octubre de 2026 | H14: 12:30 p.m. a 4:00 p.m.
A15: Envase Supply Indugral | B15: 1002777341 | C15: Antonio Guasca | D15: guascawilson797@gmail.com | E15: 314 8443067 | F15: Ingeniería Industrial | G15: 15 de octubre de 2026 | H15: 12:30 p.m. a 4:00 p.m.
A16: Envase Supply Indugral | B16: 1004154247 | C16: Cristian Alexis Gonzalez Gutiérrez | D16: cristiangonzalez842737@gmail.com | E16: 320 8753642 | F16: Ingeniería Industrial | G16: 15 de octubre de 2026 | H16: 12:30 p.m. a 4:00 p.m.
A17: Envase Supply Indugral | B17: 1004691011 | C17: Oscar Danilo Colimba Cuaical | D17: danilocuai12@gmail.com | F17: Ingeniería Mecánica | G17: 15 de octubre de 2026 | H17: 12:30 p.m. a 4:00 p.m.
A18: Envase Supply Indugral | B18: 1006101876 | C18: Alejandro Diaz Nieva | D18: alejandrodiaznieva@gmail.com | E18: 3135404291 | F18: Ingeniería Química | G18: 15 de octubre de 2026 | H18: 12:30 p.m. a 4:00 p.m.
A19: Envase Supply Indugral | B19: 1006427742 | C19: Catalina Atehortua Zuluaga | D19: catehortua310@gmail.com | E19: 323 3317100 | F19: Ingeniería Industrial | G19: 15 de octubre de 2026 | H19: 12:30 p.m. a 4:00 p.m.
A20: Envase Supply Indugral | B20: 1088589197 | C20: DIANA CAMILA MARTINEZ SOTO | D20: diana.martinez12@u.icesi.edu.co | E20: 3106456019 | F20: Ingeniería Industrial | G20: 15 de octubre de 2026 | H20: 12:30 p.m. a 4:00 p.m.
A21: Envase Supply Indugral | B21: 1089512175 | C21: Janer Darío Bolaños Quiñones | D21: dariojbq27@gmail.com | E21: 320 5293145 | F21: Ingeniería Industrial | G21: 15 de octubre de 2026 | H21: 12:30 p.m. a 4:00 p.m.
A22: Envase Supply Indugral | B22: 1193600407 | C22: Miguel Angel Salazar Ramirez | D22: miguelsalazar1105@gmail.com | E22: 314 5015242 | F22: Ingeniería Mecatrónica | G22: 15 de octubre de 2026 | H22: 12:30 p.m. a 4:00 p.m.

Sheet C.CALI
A1: Candidatos confirmados a la Creatón — Cervecería del Valle
A3: Site | B3: Cervecería del Valle
A4: Confirmación | B4: SI
A6: Vacante | B6: Cédula | C6: Nombre del candidato | D6: Correo | E6: Teléfono contacto | F6: Carrera | G6: Fecha creatón | H6: Horario creatón
A7: Calidad Cervecería del Valle | B7: 1107835167 | C7: Santiago Tamayo Quevedo | D7: santiago.tamayo3103@gmail.com | E7: 315 8084417 | F7: Ingeniería Bioquímica | G7: 21 de octubre de 2026 | H7: 7:30 a.m. a 11:30 a.m.
A8: Calidad Cervecería del Valle | B8: 1108558815 | C8: Danna Sofia Hoyos Jaramillo | D8: dannaso04@gmail.com | E8: 3157699360 | F8: Ingeniería Química | G8: 21 de octubre de 2026 | H8: 7:30 a.m. a 11:30 a.m.
A9: Calidad Cervecería del Valle | B9: 1113152043 | C9: John Edinson Agredo Muñoz | D9: johnagredo@outlook.com | E9: 3127386690 | F9: Ingeniería Industrial | G9: 21 de octubre de 2026 | H9: 7:30 a.m. a 11:30 a.m.
A10: Calidad Cervecería del Valle | B10: 1126965198 | C10: Melissa Andrea Londoño Poveda | D10: londonomelissa16@gmail.com | E10: 305 3309565 | F10: Ingeniería Industrial | G10: 21 de octubre de 2026 | H10: 7:30 a.m. a 11:30 a.m.
A11: Calidad Cervecería del Valle | B11: 1193249727 | C11: JUAN GUEVARA | D11: juan.camilo@correounivalle.edu.co | E11: 310 4297075 | F11: Ingeniería Química | G11: 21 de octubre de 2026 | H11: 7:30 a.m. a 11:30 a.m.
A12: Elaboración Cervecería del Valle | B12: 1005935212 | C12: LIZETH MAYERLI MONTENEGRO RESTREPO | D12: montenegro.lizeth@correounivalle.edu.co | E12: 318 8018223 | F12: Química | G12: 21 de octubre de 2026 | H12: 7:30 a.m. a 11:30 a.m.
A13: Elaboración Cervecería del Valle | B13: 1037776478 | C13: Maria José Oquendo Chavarría | D13: mariajoquendoch@gmail.com | E13: 300 4788939 | F13: Ingeniería Biológica | G13: 21 de octubre de 2026 | H13: 7:30 a.m. a 11:30 a.m.
A14: Elaboración Cervecería del Valle | B14: 1062275043 | C14: Maria Jose Calambas Casamachin | D14: mariajoseav52@gmail.com | E14: 310 4233492 | F14: Ingeniería de Alimentos | G14: 21 de octubre de 2026 | H14: 7:30 a.m. a 11:30 a.m.
A15: Elaboración Cervecería del Valle | B15: 1105363099 | C15: Sarah Piza Prada | D15: sarahlizethpizaprada@gmail.com | E15: 321 2048843 | F15: Ingeniería Química | G15: 21 de octubre de 2026 | H15: 7:30 a.m. a 11:30 a.m.
A16: Elaboración Cervecería del Valle | B16: 1105368091 | C16: Daniel Stiven Salinas Castillo | D16: salinas.daniel1206@gmail.com | E16: 320 7618708 | F16: Tecnología en electrónica industrial | G16: 21 de octubre de 2026 | H16: 7:30 a.m. a 11:30 a.m.
A17: Elaboración Cervecería del Valle | B17: 1105369065 | C17: Manuel Alejandro Cortés Parra | D17: alejo.cparra12@gmail.com | E17: 301 2449988 | F17: Ingeniería Industrial | G17: 21 de octubre de 2026 | H17: 7:30 a.m. a 11:30 a.m.
A18: Elaboración Cervecería del Valle | B18: 1107042882 | C18: Laura Tatiana Torres Trujillo | D18: laura.tatiana.torres@correounivalle.edu.co | E18: 315 4901789 | F18: Ingeniería Industrial | G18: 21 de octubre de 2026 | H18: 7:30 a.m. a 11:30 a.m.
... A38: Talento Cervecería del Valle | B38: 1112618688 | C38: Julian Esteban Betancourt Ocampo | D38: julianestebanbetancourt@gmail.com | E38: 317 3309191 | F38: Ingeniería Industrial | G38: 21 de octubre de 2026 | H38: 7:30 a.m. a 11:30 a.m.

Sheet C.MEDELLÍN
A1: Candidatos confirmados a la Creatón — Cervecería de Medellín
A3: Site | B3: Cervecería de Medellín
A4: Confirmación | B4: SI
A6: Vacante | B6: Cédula | C6: Nombre del candidato | D6: Correo | E6: Teléfono contacto | F6: Carrera | G6: Fecha creatón | H6: Horario creatón
A7: Elaboración Cervecería de Medellín | B7: 1029981862 | C7: Maria Paula Diaz Martinez | D7: mdiazmar@unal.edu.co | E7: 322 8949260 | F7: Ingeniería Industrial | G7: Por confirmar | H7: Por confirmar

Sheet R.ANDES
A1: Candidatos confirmados a la Creatón — Regional Andes
A3: Site | B3: Regional Andes
A4: Confirmación | B4: SI
A6: Vacante | B6: Cédula | C6: Nombre del candidato | D6: Correo | E6: Teléfono contacto | F6: Carrera | G6: Fecha creatón | H6: Horario creatón
A7: Logística T2 Regional Andes | B7: 1023523325 | C7: María Fernanda Bedoya Escobar | D7: mbedoya87@unilasallista.edu.co | E7: 321 8212815 | F7: Administración de Empresas | G7: 23 de octubre de 2026 | H7: 8:30 a.m. a 12:00 p.m.
A8: Logística T2 Regional Andes | B8: 1023523538 | C8: Yesica Alejandra Gallo Botero | D8: yesica.gallo1@udea.edu.co | E8: 310 8795621 | F8: Administración de Empresas | G8: 23 de octubre de 2026 | H8: 8:30 a.m. a 12:00 p.m.
A9: Logística T2 Regional Andes | B9: 1025880974 | C9: Manuela Lopera Monsalve | D9: manulopera2013@gmail.com | E9: 321 6544399 | F9: Administración de Empresas | G9: 23 de octubre de 2026 | H9: 8:30 a.m. a 12:00 p.m.
A10: Logística T2 Regional Andes | B10: 1034987448 | C10: Juan José Zapata | D10: jjzv2004@gmail.com | E10: 321 5798177 | F10: Negocios Internacionales | G10: 23 de octubre de 2026 | H10: 8:30 a.m. a 12:00 p.m.
A11: Logística T2 Regional Andes | B11: 1037670821 | C11: Jhon Sebastian Giraldo Pineda | D11: sebasgiraldo001@gmail.com | E11: 3113598719 | F11: Negocios Internacionales | G11: 23 de octubre de 2026 | H11: 8:30 a.m. a 12:00 p.m.
A12: Logística T2 Regional Andes | B12: 1068417699 | C12: Daniel Payares | D12: payaresdaniel20@gmail.com | E12: 319 3885124 | F12: Ingeniería Industrial | G12: 23 de octubre de 2026 | H12: 8:30 a.m. a 12:00 p.m.
A13: Logística T2 Regional Andes | B13: 1125781473 | C13: Mariana Alzate Gil | D13: marianalzate06@gmail.com | E13: 321 7538047 | F13: Negocios Internacionales | G13: 23 de octubre de 2026 | H13: 8:30 a.m. a 12:00 p.m.
A14: Ventas (gestión de ejecución premium) Regional Andes | B14: 1001095936 | C14: Daniel Felipe Hincapié López | D14: danielhincapie888@gmail.com | E14: 323 2175901 | F14: Ingeniería Industrial | G14: 23 de octubre de 2026 | H14: 8:30 a.m. a 12:00 p.m.
A15: Ventas (gestión de ejecución premium) Regional Andes | B15: 1011510808 | C15: Jennifer Giraldo | D15: jennifergiraldojaramillo@gmail.com | E15: 322 5903956 | F15: Ingeniería Administrativa | G15: 23 de octubre de 2026 | H15: 8:30 a.m. a 12:00 p.m.
